<?xml version='1.0' encoding='utf-8'?>
<robot name="combined_mobile_v4_onlyarm">
  <link name="world_x180_root" />
  <joint name="world_x180_to_combined_world_base_fixed" type="fixed">
    <parent link="world_x180_root" />
    <child link="combined_world_base" />
    <origin xyz="0 0 0" rpy="3.14159265359 0 0" />
  </joint>
  <link name="combined_world_base" />
  <link name="base_mobile">
    <inertial>
      <origin xyz="-0.029734 4.7404E-06 -0.49328" rpy="0 0 0" />
      <mass value="770.04" />
      <inertia ixx="44.031" ixy="-0.0029331" ixz="-4.071E-10" iyy="144.4" iyz="1.043E-05" izz="134.59" />
    </inertial>
    <visual>
      <origin xyz="0 0 0" rpy="3.14159265359 0 0" />
      <geometry>
        <mesh filename="/home/lflame/Desktop/bucket_robot/humanoid_urdf_assemble/meshes/base_mobile.STL" />
      </geometry>
      <material name="mobile_material_000">
        <color rgba="0.79216 0.81961 0.93333 1" />
      </material>
    </visual>
    <collision>
      <origin xyz="0 0 0" rpy="3.14159265359 0 0" />
      <geometry>
        <mesh filename="/home/lflame/Desktop/bucket_robot/humanoid_urdf_assemble/meshes/base_mobile.STL" />
      </geometry>
    </collision>
  </link>
  <link name="body1_mobile">
    <inertial>
      <origin xyz="0.0017346 0.24458 0.14075" rpy="0 0 0" />
      <mass value="155.24" />
      <inertia ixx="103.89" ixy="-8.8363E-15" ixz="0.00012602" iyy="101.24" iyz="-2.3877" izz="6.1346" />
    </inertial>
    <visual>
      <origin xyz="0 0 0" rpy="0 0 0" />
      <geometry>
        <mesh filename="/home/lflame/Desktop/bucket_robot/humanoid_urdf_assemble/meshes/body1_mobile.STL" />
      </geometry>
      <material name="mobile_material_000">
        <color rgba="0.79216 0.81961 0.93333 1" />
      </material>
    </visual>
    <collision>
      <origin xyz="0 0 0" rpy="0 0 0" />
      <geometry>
        <mesh filename="/home/lflame/Desktop/bucket_robot/humanoid_urdf_assemble/meshes/body1_mobile.STL" />
      </geometry>
    </collision>
  </link>
  <link name="body2_mobile">
    <inertial>
      <origin xyz="-2.0228E-13 -0.095664 1.8318" rpy="0 0 0" />
      <mass value="43.419" />
      <inertia ixx="24.458" ixy="-7.6949E-17" ixz="-8.9897E-14" iyy="24.396" iyz="-0.0028657" izz="0.50893" />
    </inertial>
    <visual>
      <origin xyz="0 0 0" rpy="0 0 0" />
      <geometry>
        <mesh filename="/home/lflame/Desktop/bucket_robot/humanoid_urdf_assemble/meshes/body2_mobile.STL" />
      </geometry>
      <material name="mobile_material_000">
        <color rgba="0.79216 0.81961 0.93333 1" />
      </material>
    </visual>
    <collision>
      <origin xyz="0 0 0" rpy="0 0 0" />
      <geometry>
        <mesh filename="/home/lflame/Desktop/bucket_robot/humanoid_urdf_assemble/meshes/body2_mobile.STL" />
      </geometry>
    </collision>
  </link>
  <link name="body3_mobile">
    <inertial>
      <origin xyz="-0.257562906512611 0.0416042660645409 3.16481912527587E-13" rpy="0 0 0" />
      <mass value="29.1600336472618" />
      <inertia ixx="3.27987912830083" ixy="0.024122753378786" ixz="1.21786162209115E-17" iyy="0.591373123584008" iyz="-1.87045743115935E-18" izz="3.73858991924119" />
    </inertial>
    <visual>
      <origin xyz="0 0 0" rpy="0 0 0" />
      <geometry>
        <mesh filename="/home/lflame/Desktop/bucket_robot/humanoid_urdf_assemble/meshes/body3_mobile.STL" />
      </geometry>
      <material name="mobile_material_000">
        <color rgba="0.792156862745098 0.819607843137255 0.933333333333333 1" />
      </material>
    </visual>
    <collision>
      <origin xyz="0 0 0" rpy="0 0 0" />
      <geometry>
        <mesh filename="/home/lflame/Desktop/bucket_robot/humanoid_urdf_assemble/meshes/body3_mobile.STL" />
      </geometry>
    </collision>
  </link>
  <link name="body4_mobile">
    <inertial>
      <origin xyz="3.46281331755033 -0.0675991274887173 -0.000158391344936916" rpy="0 0 0" />
      <mass value="109.07285027416" />
      <inertia ixx="2.72864804555609" ixy="0.010753184530907" ixz="9.5066271913632E-05" iyy="327.684154741602" iyz="-1.12246217710802E-06" izz="328.632979625957" />
    </inertial>
    <visual>
      <origin xyz="0 0 0" rpy="0 0 0" />
      <geometry>
        <mesh filename="/home/lflame/Desktop/bucket_robot/humanoid_urdf_assemble/meshes/body4_mobile.STL" />
      </geometry>
      <material name="mobile_material_000">
        <color rgba="0.792156862745098 0.819607843137255 0.933333333333333 1" />
      </material>
    </visual>
    <collision>
      <origin xyz="0 0 0" rpy="0 0 0" />
      <geometry>
        <mesh filename="/home/lflame/Desktop/bucket_robot/humanoid_urdf_assemble/meshes/body4_mobile.STL" />
      </geometry>
    </collision>
  </link>
  <link name="body5_mobile">
    <inertial>
      <origin xyz="0.128160580269422 -0.0467069527336996 2.46807734871604E-15" rpy="0 0 0" />
      <mass value="1.59541005070581" />
      <inertia ixx="0.0217462102376676" ixy="-0.00130681251880065" ixz="-3.28890410956385E-18" iyy="0.00926234598382728" iyz="1.1796241215884E-19" izz="0.0309819660539831" />
    </inertial>
    <visual>
      <origin xyz="0 0 0" rpy="0 0 0" />
      <geometry>
        <mesh filename="/home/lflame/Desktop/bucket_robot/humanoid_urdf_assemble/meshes/body5_mobile.STL" />
      </geometry>
      <material name="mobile_material_000">
        <color rgba="0.792156862745098 0.819607843137255 0.933333333333333 1" />
      </material>
    </visual>
    <collision>
      <origin xyz="0 0 0" rpy="0 0 0" />
      <geometry>
        <mesh filename="/home/lflame/Desktop/bucket_robot/humanoid_urdf_assemble/meshes/body5_mobile.STL" />
      </geometry>
    </collision>
  </link>
  <link name="body6_mobile">
    <inertial>
      <origin xyz="0.89637194364498 0.00432299706104544 1.00968826197784E-15" rpy="0 0 0" />
      <mass value="6.29959038280337" />
      <inertia ixx="0.0314600318769282" ixy="-0.000119133325305261" ixz="1.77667721499361E-15" iyy="0.846469015877942" iyz="-1.16698166481591E-17" izz="0.846602876941725" />
    </inertial>
    <visual>
      <origin xyz="0 0 0" rpy="0 0 0" />
      <geometry>
        <mesh filename="/home/lflame/Desktop/bucket_robot/humanoid_urdf_assemble/meshes/body6_mobile.STL" />
      </geometry>
      <material name="mobile_material_000">
        <color rgba="0.792156862745098 0.819607843137255 0.933333333333333 1" />
      </material>
    </visual>
    <collision>
      <origin xyz="0 0 0" rpy="0 0 0" />
      <geometry>
        <mesh filename="/home/lflame/Desktop/bucket_robot/humanoid_urdf_assemble/meshes/body6_mobile.STL" />
      </geometry>
    </collision>
  </link>
  <link name="body7_mobile">
    <inertial>
      <origin xyz="4.2327463974723E-05 -0.148498627040513 -0.132884058752502" rpy="0 0 0" />
      <mass value="3.19458463723707" />
      <inertia ixx="0.0266228592880333" ixy="2.61720788127551E-06" ixz="2.76551377919451E-05" iyy="0.0217649970327056" iyz="0.00431418725685377" izz="0.0177594693280646" />
    </inertial>
    <visual>
      <origin xyz="0 0 0" rpy="0 0 0" />
      <geometry>
        <mesh filename="/home/lflame/Desktop/bucket_robot/humanoid_urdf_assemble/meshes/body7_mobile.STL" />
      </geometry>
      <material name="mobile_material_000">
        <color rgba="0.792156862745098 0.819607843137255 0.933333333333333 1" />
      </material>
    </visual>
    <collision>
      <origin xyz="0 0 0" rpy="0 0 0" />
      <geometry>
        <mesh filename="/home/lflame/Desktop/bucket_robot/humanoid_urdf_assemble/meshes/body7_mobile.STL" />
      </geometry>
    </collision>
  </link>
  <link name="body8_mobile">
    <inertial>
      <origin xyz="7.35495733425597E-05 -0.11034551663069 0.189790385815516" rpy="0 0 0" />
      <mass value="3.10804416652657" />
      <inertia ixx="0.0222321405156742" ixy="-4.42334573878136E-09" ixz="1.41671735044325E-16" iyy="0.103723387347221" iyz="1.58948814888947E-05" izz="0.0953099221755763" />
    </inertial>
    <visual>
      <origin xyz="0 0 0" rpy="0 0 0" />
      <geometry>
        <mesh filename="/home/lflame/Desktop/bucket_robot/humanoid_urdf_assemble/meshes/body8_mobile.STL" />
      </geometry>
      <material name="mobile_material_000">
        <color rgba="0.792156862745098 0.819607843137255 0.933333333333333 1" />
      </material>
    </visual>
    <collision>
      <origin xyz="0 0 0" rpy="0 0 0" />
      <geometry>
        <mesh filename="/home/lflame/Desktop/bucket_robot/humanoid_urdf_assemble/meshes/body8_mobile.STL" />
      </geometry>
    </collision>
  </link>
  <joint name="joint1_mobile" type="revolute">
    <origin xyz="0 -0.146 0" rpy="0 -1.5708 0" />
    <parent link="base_mobile" />
    <child link="body1_mobile" />
    <axis xyz="0 1 0" />
    <limit lower="0" upper="0" effort="0" velocity="0" />
  </joint>
  <joint name="joint2_mobile" type="revolute">
    <origin xyz="0 0.71467 1.4217" rpy="-3.0631 0 -3.1416" />
    <parent link="body1_mobile" />
    <child link="body2_mobile" />
    <axis xyz="1 0 0" />
    <limit lower="0" upper="0" effort="0" velocity="0" />
  </joint>
  <joint name="joint3_mobile" type="revolute">
    <origin xyz="0 -3.0827E-05 3.6492" rpy="-1.5708 1.4923 -1.5708" />
    <parent link="body2_mobile" />
    <child link="body3_mobile" />
    <axis xyz="0 0 1" />
    <limit lower="0" upper="0" effort="0" velocity="0" />
  </joint>
  <joint name="joint4_mobile" type="revolute">
    <origin xyz="-0.32402 0.67267 0" rpy="0 0 -0.063879" />
    <parent link="body3_mobile" />
    <child link="body4_mobile" />
    <axis xyz="0 0 1" />
    <limit lower="0" upper="0" effort="0" velocity="0" />
  </joint>
  <joint name="joint5_mobile" type="revolute">
    <origin xyz="7.4983 0.033857 0" rpy="0 0 0.16947" />
    <parent link="body4_mobile" />
    <child link="body5_mobile" />
    <axis xyz="0 0 1" />
    <limit lower="0" upper="0" effort="0" velocity="0" />
  </joint>
  <joint name="joint6_mobile" type="revolute">
    <origin xyz="0.20463 0.14401 0" rpy="0 0 -0.79343" />
    <parent link="body5_mobile" />
    <child link="body6_mobile" />
    <axis xyz="0 0 1" />
    <limit lower="0" upper="0" effort="0" velocity="0" />
  </joint>
  <joint name="joint7_mobile" type="revolute">
    <origin xyz="1.72 -0.019163 0" rpy="2.7295 1.5708 0" />
    <parent link="body6_mobile" />
    <child link="body7_mobile" />
    <axis xyz="1 0 0" />
    <limit lower="0" upper="0" effort="0" velocity="0" />
  </joint>
  <joint name="joint8_mobile" type="revolute">
    <origin xyz="0 -0.25367 0.01" rpy="1.5708 0 0" />
    <parent link="body7_mobile" />
    <child link="body8_mobile" />
    <axis xyz="0 1 0" />
    <limit lower="0" upper="0" effort="0" velocity="0" />
  </joint>
  <link name="base">
    <inertial>
      <origin xyz="-9.83860433156902E-06 0.149850814670592 -0.791226497586037" rpy="0 0 0" />
      <mass value="210.520145508308" />
      <inertia ixx="94.6081580348792" ixy="-4.79354583401981E-05" ixz="4.48798056105204E-05" iyy="115.632562660079" iyz="11.8397721927448" izz="145.89854453167" />
    </inertial>
    <visual>
      <origin xyz="0 0 0" rpy="0 0 0" />
      <geometry>
        <mesh filename="/home/lflame/Desktop/bucket_robot/humanoid_urdf_assemble/meshes/base.STL" />
      </geometry>
      <material name="onlyarm_material_000">
        <color rgba="0.501960784313725 0.501960784313725 0.501960784313725 1" />
      </material>
    </visual>
    <collision>
      <origin xyz="0 0 0" rpy="0 0 0" />
      <geometry>
        <mesh filename="/home/lflame/Desktop/bucket_robot/humanoid_urdf_assemble/meshes/base.STL" />
      </geometry>
    </collision>
  </link>
  <link name="link1">
    <inertial>
      <origin xyz="2.47397317565679E-05 0.00352448443745301 0.0520878199267876" rpy="0 0 0" />
      <mass value="2.94161243820951" />
      <inertia ixx="0.0106200517809992" ixy="-1.89261933122907E-05" ixz="3.06857456854742E-06" iyy="0.0099234023538503" iyz="0.000162263144311159" izz="0.0150373111967169" />
    </inertial>
    <visual>
      <origin xyz="0 0 0" rpy="0 0 0" />
      <geometry>
        <mesh filename="/home/lflame/Desktop/bucket_robot/humanoid_urdf_assemble/meshes/link1.STL" />
      </geometry>
      <material name="onlyarm_material_000">
        <color rgba="0.792156862745098 0.819607843137255 0.933333333333333 1" />
      </material>
    </visual>
    <collision>
      <origin xyz="0 0 0" rpy="0 0 0" />
      <geometry>
        <mesh filename="/home/lflame/Desktop/bucket_robot/humanoid_urdf_assemble/meshes/link1.STL" />
      </geometry>
    </collision>
  </link>
  <link name="link2">
    <inertial>
      <origin xyz="7.74338783982031E-06 0.0180015719133768 0.159974541111227" rpy="0 0 0" />
      <mass value="2.60281502325875" />
      <inertia ixx="0.00840565671974392" ixy="2.30648230617795E-06" ixz="-2.12745422034752E-06" iyy="0.00855603041378285" iyz="0.00228222512468144" izz="0.0087907870152715" />
    </inertial>
    <visual>
      <origin xyz="0 0 0" rpy="0 0 0" />
      <geometry>
        <mesh filename="/home/lflame/Desktop/bucket_robot/humanoid_urdf_assemble/meshes/link2.STL" />
      </geometry>
      <material name="onlyarm_material_000">
        <color rgba="0.792156862745098 0.819607843137255 0.933333333333333 1" />
      </material>
    </visual>
    <collision>
      <origin xyz="0 0 0" rpy="0 0 0" />
      <geometry>
        <mesh filename="/home/lflame/Desktop/bucket_robot/humanoid_urdf_assemble/meshes/link2.STL" />
      </geometry>
    </collision>
  </link>
  <link name="link3">
    <inertial>
      <origin xyz="-1.34934652801233E-06 -0.25294340565573 0.46477016468655" rpy="0 0 0" />
      <mass value="18.7646252623897" />
      <inertia ixx="0.486219714792646" ixy="-2.2898043345208E-06" ixz="2.37493364689577E-06" iyy="0.486996079085685" iyz="-1.4727219019085E-05" izz="0.0565979506075105" />
    </inertial>
    <visual>
      <origin xyz="0 0 0" rpy="0 0 0" />
      <geometry>
        <mesh filename="/home/lflame/Desktop/bucket_robot/humanoid_urdf_assemble/meshes/link3.STL" />
      </geometry>
      <material name="onlyarm_material_000">
        <color rgba="0.792156862745098 0.819607843137255 0.933333333333333 1" />
      </material>
    </visual>
    <collision>
      <origin xyz="0 0 0" rpy="0 0 0" />
      <geometry>
        <mesh filename="/home/lflame/Desktop/bucket_robot/humanoid_urdf_assemble/meshes/link3.STL" />
      </geometry>
    </collision>
  </link>
  <link name="link4">
    <inertial>
      <origin xyz="2.8852401111612E-06 -0.0773598865373835 0.0134636505554932" rpy="0 0 0" />
      <mass value="3.54298234055506" />
      <inertia ixx="0.00990031290094014" ixy="-1.06839609390411E-08" ixz="1.78804412162678E-07" iyy="0.0101542545778609" iyz="-0.00229697867831994" izz="0.0102838440330496" />
    </inertial>
    <visual>
      <origin xyz="0 0 0" rpy="0 0 0" />
      <geometry>
        <mesh filename="/home/lflame/Desktop/bucket_robot/humanoid_urdf_assemble/meshes/link4.STL" />
      </geometry>
      <material name="onlyarm_material_000">
        <color rgba="0.792156862745098 0.819607843137255 0.933333333333333 1" />
      </material>
    </visual>
    <collision>
      <origin xyz="0 0 0" rpy="0 0 0" />
      <geometry>
        <mesh filename="/home/lflame/Desktop/bucket_robot/humanoid_urdf_assemble/meshes/link4.STL" />
      </geometry>
    </collision>
  </link>
  <link name="link5">
    <inertial>
      <origin xyz="4.41152676133871E-06 -0.0700886795213416 0.372406971073142" rpy="0 0 0" />
      <mass value="10.1984648970475" />
      <inertia ixx="0.385474985386779" ixy="3.97382458265649E-07" ixz="-4.47657157109319E-07" iyy="0.358972897183227" iyz="0.0890479388755992" izz="0.0472591746542673" />
    </inertial>
    <visual>
      <origin xyz="0 0 0" rpy="0 0 0" />
      <geometry>
        <mesh filename="/home/lflame/Desktop/bucket_robot/humanoid_urdf_assemble/meshes/link5.STL" />
      </geometry>
      <material name="onlyarm_material_000">
        <color rgba="0.792156862745098 0.819607843137255 0.933333333333333 1" />
      </material>
    </visual>
    <collision>
      <origin xyz="0 0 0" rpy="0 0 0" />
      <geometry>
        <mesh filename="/home/lflame/Desktop/bucket_robot/humanoid_urdf_assemble/meshes/link5.STL" />
      </geometry>
    </collision>
  </link>
  <link name="link6">
    <inertial>
      <origin xyz="-3.10838969935778E-06 -0.00458683841173568 0.00954381967293139" rpy="0 0 0" />
      <mass value="1.17891671081572" />
      <inertia ixx="0.00135048924847834" ixy="-9.01775348445262E-10" ixz="-3.27431999942958E-08" iyy="0.00136380336368904" iyz="-0.000318692852165411" izz="0.00143060472609911" />
    </inertial>
    <visual>
      <origin xyz="0 0 0" rpy="0 0 0" />
      <geometry>
        <mesh filename="/home/lflame/Desktop/bucket_robot/humanoid_urdf_assemble/meshes/link6.STL" />
      </geometry>
      <material name="onlyarm_material_000">
        <color rgba="0.792156862745098 0.819607843137255 0.933333333333333 1" />
      </material>
    </visual>
    <collision>
      <origin xyz="0 0 0" rpy="0 0 0" />
      <geometry>
        <mesh filename="/home/lflame/Desktop/bucket_robot/humanoid_urdf_assemble/meshes/link6.STL" />
      </geometry>
    </collision>
  </link>
  <link name="link7">
    <inertial>
      <origin xyz="-2.37394919248013E-05 -0.0003354858152253 0.0365056983720199" rpy="0 0 0" />
      <mass value="0.424230999670951" />
      <inertia ixx="0.000299223647867548" ixy="-1.33004676248762E-08" ixz="1.66920321055874E-07" iyy="0.000302897609556963" iyz="2.23102679888702E-08" izz="0.000490641798779995" />
    </inertial>
    <visual>
      <origin xyz="0 0 0" rpy="0 0 0" />
      <geometry>
        <mesh filename="/home/lflame/Desktop/bucket_robot/humanoid_urdf_assemble/meshes/link7.STL" />
      </geometry>
      <material name="onlyarm_material_000">
        <color rgba="0.792156862745098 0.819607843137255 0.933333333333333 1" />
      </material>
    </visual>
    <collision>
      <origin xyz="0 0 0" rpy="0 0 0" />
      <geometry>
        <mesh filename="/home/lflame/Desktop/bucket_robot/humanoid_urdf_assemble/meshes/link7.STL" />
      </geometry>
    </collision>
  </link>
  <link name="link8">
    <inertial>
      <origin xyz="2.47368995258679E-05 0.00352448407270206 0.0520878206292635" rpy="0 0 0" />
      <mass value="2.94161256403145" />
      <inertia ixx="0.0106200518685206" ixy="-1.89262230043393E-05" ixz="3.06885688599549E-06" iyy="0.00992340269513543" iyz="0.000162263202577407" izz="0.0150373114809957" />
    </inertial>
    <visual>
      <origin xyz="0 0 0" rpy="0 0 0" />
      <geometry>
        <mesh filename="/home/lflame/Desktop/bucket_robot/humanoid_urdf_assemble/meshes/link8.STL" />
      </geometry>
      <material name="onlyarm_material_000">
        <color rgba="0.792156862745098 0.819607843137255 0.933333333333333 1" />
      </material>
    </visual>
    <collision>
      <origin xyz="0 0 0" rpy="0 0 0" />
      <geometry>
        <mesh filename="/home/lflame/Desktop/bucket_robot/humanoid_urdf_assemble/meshes/link8.STL" />
      </geometry>
    </collision>
  </link>
  <link name="link9">
    <inertial>
      <origin xyz="7.77735156687331E-06 0.0180015592736388 0.159721266604027" rpy="0 0 0" />
      <mass value="2.60281476891797" />
      <inertia ixx="0.00840565625279258" ixy="2.30654280884875E-06" ixz="-2.12719701174962E-06" iyy="0.00855602792804681" iyz="0.00228222549355325" izz="0.00879078520216804" />
    </inertial>
    <visual>
      <origin xyz="0 0 0" rpy="0 0 0" />
      <geometry>
        <mesh filename="/home/lflame/Desktop/bucket_robot/humanoid_urdf_assemble/meshes/link9.STL" />
      </geometry>
      <material name="onlyarm_material_000">
        <color rgba="0.792156862745098 0.819607843137255 0.933333333333333 1" />
      </material>
    </visual>
    <collision>
      <origin xyz="0 0 0" rpy="0 0 0" />
      <geometry>
        <mesh filename="/home/lflame/Desktop/bucket_robot/humanoid_urdf_assemble/meshes/link9.STL" />
      </geometry>
    </collision>
  </link>
  <link name="link10">
    <inertial>
      <origin xyz="-1.59071214184126E-06 -0.138386121837291 0.464767303309509" rpy="0 0 0" />
      <mass value="18.7644925307955" />
      <inertia ixx="0.4862195927679" ixy="-2.23261086949183E-06" ixz="2.3263001411117E-06" iyy="0.486996021794847" iyz="-1.46520016949545E-05" izz="0.0565978165857408" />
    </inertial>
    <visual>
      <origin xyz="0 0 0" rpy="0 0 0" />
      <geometry>
        <mesh filename="/home/lflame/Desktop/bucket_robot/humanoid_urdf_assemble/meshes/link10.STL" />
      </geometry>
      <material name="onlyarm_material_000">
        <color rgba="0.792156862745098 0.819607843137255 0.933333333333333 1" />
      </material>
    </visual>
    <collision>
      <origin xyz="0 0 0" rpy="0 0 0" />
      <geometry>
        <mesh filename="/home/lflame/Desktop/bucket_robot/humanoid_urdf_assemble/meshes/link10.STL" />
      </geometry>
    </collision>
  </link>
  <link name="link11">
    <inertial>
      <origin xyz="2.84099025610329E-06 0.0371971240997369 0.0134636383184765" rpy="0 0 0" />
      <mass value="3.54298720803755" />
      <inertia ixx="0.00990031561779054" ixy="-9.21392123449244E-09" ixz="1.81431762920125E-07" iyy="0.0101542551614307" iyz="-0.00229698072803488" izz="0.0102838497935322" />
    </inertial>
    <visual>
      <origin xyz="0 0 0" rpy="0 0 0" />
      <geometry>
        <mesh filename="/home/lflame/Desktop/bucket_robot/humanoid_urdf_assemble/meshes/link11.STL" />
      </geometry>
      <material name="onlyarm_material_000">
        <color rgba="0.792156862745098 0.819607843137255 0.933333333333333 1" />
      </material>
    </visual>
    <collision>
      <origin xyz="0 0 0" rpy="0 0 0" />
      <geometry>
        <mesh filename="/home/lflame/Desktop/bucket_robot/humanoid_urdf_assemble/meshes/link11.STL" />
      </geometry>
    </collision>
  </link>
  <link name="link12">
    <inertial>
      <origin xyz="5.40252041880684E-06 -0.0700886042602085 0.346392400887851" rpy="0 0 0" />
      <mass value="10.199072921449" />
      <inertia ixx="0.385474353254966" ixy="2.24096969266008E-07" ixz="-1.29724995299443E-07" iyy="0.358973121159461" iyz="0.0890476185117296" izz="0.0472590447319512" />
    </inertial>
    <visual>
      <origin xyz="0 0 0" rpy="0 0 0" />
      <geometry>
        <mesh filename="/home/lflame/Desktop/bucket_robot/humanoid_urdf_assemble/meshes/link12.STL" />
      </geometry>
      <material name="onlyarm_material_000">
        <color rgba="0.792156862745098 0.819607843137255 0.933333333333333 1" />
      </material>
    </visual>
    <collision>
      <origin xyz="0 0 0" rpy="0 0 0" />
      <geometry>
        <mesh filename="/home/lflame/Desktop/bucket_robot/humanoid_urdf_assemble/meshes/link12.STL" />
      </geometry>
    </collision>
  </link>
  <link name="link13">
    <inertial>
      <origin xyz="-3.24302008664068E-06 -0.00458681527894433 0.00954373507083073" rpy="0 0 0" />
      <mass value="1.17892032472978" />
      <inertia ixx="0.00135049864106432" ixy="5.3453289619701E-09" ixz="-3.06591933948919E-08" iyy="0.00136379715245524" iyz="-0.000318697330315532" izz="0.00143059856691417" />
    </inertial>
    <visual>
      <origin xyz="0 0 0" rpy="0 0 0" />
      <geometry>
        <mesh filename="/home/lflame/Desktop/bucket_robot/humanoid_urdf_assemble/meshes/link13.STL" />
      </geometry>
      <material name="onlyarm_material_000">
        <color rgba="0.792156862745098 0.819607843137255 0.933333333333333 1" />
      </material>
    </visual>
    <collision>
      <origin xyz="0 0 0" rpy="0 0 0" />
      <geometry>
        <mesh filename="/home/lflame/Desktop/bucket_robot/humanoid_urdf_assemble/meshes/link13.STL" />
      </geometry>
    </collision>
  </link>
  <link name="link14">
    <inertial>
      <origin xyz="-2.37401461800069E-05 -0.000335469381670339 0.0387936900804668" rpy="0 0 0" />
      <mass value="0.424231147330343" />
      <inertia ixx="0.00029922365171465" ixy="-1.32999743167569E-08" ixz="1.66919162826909E-07" iyy="0.000302897612098239" iyz="2.23109782769438E-08" izz="0.000490641802353995" />
    </inertial>
    <visual>
      <origin xyz="0 0 0" rpy="0 0 0" />
      <geometry>
        <mesh filename="/home/lflame/Desktop/bucket_robot/humanoid_urdf_assemble/meshes/link14.STL" />
      </geometry>
      <material name="onlyarm_material_000">
        <color rgba="0.792156862745098 0.819607843137255 0.933333333333333 1" />
      </material>
    </visual>
    <collision>
      <origin xyz="0 0 0" rpy="0 0 0" />
      <geometry>
        <mesh filename="/home/lflame/Desktop/bucket_robot/humanoid_urdf_assemble/meshes/link14.STL" />
      </geometry>
    </collision>
  </link>
  <joint name="joint1" type="continuous">
    <origin xyz="0.345 0 0" rpy="1.5707963267949 -0.0732624051864699 -3.14159265358979" />
    <limit lower="-3.14159" upper="3.14159" effort="50" velocity="2.0" />
    <parent link="base" />
    <child link="link1" />
    <axis xyz="0 0 1" />
  </joint>
  <joint name="joint2" type="continuous">
    <origin xyz="0 0 0.0935489449635794" rpy="0 0 -1.60570163938842" />
    <limit lower="-3.14159" upper="3.14159" effort="50" velocity="2.0" />
    <parent link="link1" />
    <child link="link2" />
    <axis xyz="0 0 1" />
  </joint>
  <joint name="joint3" type="continuous">
    <origin xyz="0 -0.00034898225030594 0.14675105503642" rpy="3.14159265358972 1.53372688920277 3.14159265358973" />
    <limit lower="-3.14159" upper="3.14159" effort="50" velocity="2.0" />
    <parent link="link2" />
    <child link="link3" />
    <axis xyz="0 1 0" />
  </joint>
  <joint name="joint4" type="continuous">
    <origin xyz="0 0 0.884999999999989" rpy="3.14159265358899 -1.55530909308773 -3.14159265358899" />
    <limit lower="-3.14159" upper="3.14159" effort="50" velocity="2.0" />
    <parent link="link3" />
    <child link="link4" />
    <axis xyz="0 1 0" />
  </joint>
  <joint name="joint5" type="continuous">
    <origin xyz="0 -0.0661510177497045 0.0762615293319013" rpy="0 0 1.52575034019283" />
    <limit lower="-3.14159" upper="3.14159" effort="50" velocity="2.0" />
    <parent link="link4" />
    <child link="link5" />
    <axis xyz="0 0 1" />
  </joint>
  <joint name="joint6" type="continuous">
    <origin xyz="0 0 0.808738470668031" rpy="0 -0.0807964323798433 0" />
    <limit lower="-3.14159" upper="3.14159" effort="50" velocity="2.0" />
    <parent link="link5" />
    <child link="link6" />
    <axis xyz="0 1 0" />
  </joint>
  <joint name="joint7" type="continuous">
    <origin xyz="0 0 0.0631892387201386" rpy="0 0 0.377893780004331" />
    <limit lower="-3.14159" upper="3.14159" effort="50" velocity="2.0" />
    <parent link="link6" />
    <child link="link7" />
    <axis xyz="0 0 1" />
  </joint>
  <joint name="joint8" type="continuous">
    <origin xyz="-0.345000000000007 0 0" rpy="-1.57079632679489 1.27572975941174 0" />
    <limit lower="-3.14159" upper="3.14159" effort="50" velocity="2.0" />
    <parent link="base" />
    <child link="link8" />
    <axis xyz="0 0 1" />
  </joint>
  <joint name="joint9" type="continuous">
    <origin xyz="0 0 0.0938022498685929" rpy="0 0 -2.88720498390202" />
    <limit lower="-3.14159" upper="3.14159" effort="50" velocity="2.0" />
    <parent link="link8" />
    <child link="link9" />
    <axis xyz="0 0 1" />
  </joint>
  <joint name="joint10" type="continuous">
    <origin xyz="0 -0.114905991968565 0.146497750131407" rpy="0 -1.49739535144737 0" />
    <limit lower="-3.14159" upper="3.14159" effort="50" velocity="2.0" />
    <parent link="link9" />
    <child link="link10" />
    <axis xyz="0 1 0" />
  </joint>
  <joint name="joint11" type="continuous">
    <origin xyz="0 0 0.884999999999988" rpy="3.1415926535896 1.54270044917624 3.14159265358961" />
    <limit lower="-3.14159" upper="3.14159" effort="50" velocity="2.0" />
    <parent link="link10" />
    <child link="link11" />
    <axis xyz="0 1 0" />
  </joint>
  <joint name="joint12" type="continuous">
    <origin xyz="0 0.0484059919685519 0.102266694569716" rpy="0 0 -1.59261680536769" />
    <limit lower="-3.14159" upper="3.14159" effort="50" velocity="2.0" />
    <parent link="link11" />
    <child link="link12" />
    <axis xyz="0 0 1" />
  </joint>
  <joint name="joint13" type="continuous">
    <origin xyz="0 0 0.782733305430217" rpy="0 0.147690992576578 0" />
    <limit lower="-3.14159" upper="3.14159" effort="50" velocity="2.0" />
    <parent link="link12" />
    <child link="link13" />
    <axis xyz="0 1 0" />
  </joint>
  <joint name="joint14" type="continuous">
    <origin xyz="0 0 0.0609012471271789" rpy="0 0 -3.04502373934799" />
    <limit lower="-3.14159" upper="3.14159" effort="50" velocity="2.0" />
    <parent link="link13" />
    <child link="link14" />
    <axis xyz="0 0 1" />
  </joint>
  <joint name="combined_world_to_mobile_base_fixed" type="fixed">
    <origin xyz="0 0 0" rpy="-1.57079632679 0 0" />
    <parent link="combined_world_base" />
    <child link="base_mobile" />
  </joint>
  <joint name="mobile_body8_to_onlyarm_base_fixed" type="fixed">
    <origin xyz="0 0 0" rpy="0 0 3.141592" />
    <parent link="body8_mobile" />
    <child link="base" />
  </joint>
</robot>